Workbook

Sheet 1 Исходные данные
A1: Задание 1. Таблица исходных данных
A2: ПАО «Татнефть» им. В.Д. Шашина, бухгалтерская отчетность РСБУ. Сравнительный 2024 год взят из отчета за 2025 после корректировок (ФСБУ 4/2023). Единица — млн руб., в отчете числа даны в тыс. руб.
A3: Показатель | B3: 2024 год | C3: 2025 год | D3: Ед. | E3: Документ / номер строки / первоисточник
A4: Выручка | B4: 1563778.4 | C4: 1379916.4 | D4: млн руб. | E4: ОФР 2110; бухгалтерская отчётность ПАО, опубликована через e-disclosure; архив PDF: https://reportcollection.inion.ru/reports/download/?reportId=4664
A5: Себестоимость продаж | B5: 1118130.8 | C5: 1046338.3 | D5: млн руб. | E5: ОФР, строка 2120 https://reportcollection.inion.ru/reports/download/?reportId=4664
A6: Валовая прибыль | B6: 445647.57 | C6: 333578.09 | D6: млн руб. | E6: ОФР, строка 2100 https://reportcollection.inion.ru/reports/download/?reportId=4664
A7: Коммерческие расходы | B7: 110103.05 | C7: 94772.838 | D7: млн руб. | E7: ОФР, строка 2210 · https://reportcollection.inion.ru/reports/download/?reportId=4664
A8: Управленческие расходы | B8: 16444.301 | C8: 16224.622 | D8: млн руб. | E8: ОФР, строка 2220 · https://reportcollection.inion.ru/reports/download/?reportId=4664
A9: Прибыль от продаж | B9: 319100.22 | C9: 222580.63 | D9: млн руб. | E9: ОФР, строка 2200 · https://reportcollection.inion.ru/reports/download/?reportId=4664
A10: Прибыль до налогообложения | B10: 330000.92 | C10: 188891.94 | D10: млн руб. | E10: ОФР, строка 2300 · https://reportcollection.inion.ru/reports/download/?reportId=4664
A11: Чистая прибыль | B11: 251375.29 | C11: 145844.14 | D11: млн руб. | E11: ОФР, строка 2400 · https://reportcollection.inion.ru/reports/download/?reportId=4664
A12: Амортизация (расходы по обычным видам деятельности) | B12: 35650.873 | C12: 40988.345 | D12: млн руб. | E12: Пояснение 12, амортизация в расходах по обычным видам деятельности · https://reportcollection.inion.ru/reports/download/?reportId=4664
A13: ОДП / операционный денежный поток | B13: 291900.47 | C13: 207008.76 | D13: млн руб. | E13: ОДДС, строка 4100 · https://reportcollection.inion.ru/reports/download/?reportId=4664
A14: Капвложения: платежи инвестиционной деятельности | B14: 92737.396 | C14: 67359.138 | D14: млн руб. | E14: ОДДС, строка 4221 · https://reportcollection.inion.ru/reports/download/?reportId=4664
A15: Капвложения: платежи текущей деятельности | B15: 35430.835 | C15: 31513.716 | D15: млн руб. | E15: ОДДС, строка 4125 · https://reportcollection.inion.ru/reports/download/?reportId=4664
... A28: Выручка: прочая реализация | B28: 14151.351 | C28: 13744.951 | D28: млн руб. | E28: Пояснение 11, прочая реализация · https://reportcollection.inion.ru/reports/download/?reportId=4664
A31: Баланс на три отчетные даты, млн руб.
A32: Показатель | B32: 31.12.2024 | C32: 31.12.2025 | D32: 31.12.2023 | E32: Источник
A33: Активы всего | B33: 1493117.7 | C33: 1407313.7 | D33: 1455562.3 | E33: Бухгалтерский баланс / https://reportcollection.inion.ru/reports/download/?reportId=4664
A34: Основные средства | B34: 456703.33 | C34: 480741.73 | D34: 389688.51 | E34: Бухгалтерский баланс / https://reportcollection.inion.ru/reports/download/?reportId=4664
A35: Запасы | B35: 184900.3 | C35: 134947.44 | D35: 156011.32 | E35: Бухгалтерский баланс / https://reportcollection.inion.ru/reports/download/?reportId=4664
A36: Дебиторская задолженность | B36: 348152.28 | C36: 321044.41 | D36: 396241.26 | E36: Бухгалтерский баланс / https://reportcollection.inion.ru/reports/download/?reportId=4664
A37: Денежные средства | B37: 64365.22 | C37: 31358.287 | D37: 52642.849 | E37: Бухгалтерский баланс / https://reportcollection.inion.ru/reports/download/?reportId=4664
A38: Собственный капитал | B38: 992130.68 | C38: 983687.04 | D38: 927820.36 | E38: Бухгалтерский баланс / https://reportcollection.inion.ru/reports/download/?reportId=4664
A39: Краткосрочные обязательства | B39: 403179.46 | C39: 330377.36 | D39: 451784.92 | E39: Бухгалтерский баланс / https://reportcollection.inion.ru/reports/download/?reportId=4664
A40: Долгосрочные обязательства | B40: 97807.535 | C40: 93249.336 | D40: 75957.03 | E40: Бухгалтерский баланс / https://reportcollection.inion.ru/reports/download/?reportId=4664
A42: Контроль равенств по отчетности:
A43: Выручка − себестоимость − валовая прибыль = 0 | B43: =B4-B5-B6 | C43: =C4-C5-C6
A44: Валовая − коммерч. − управленч. − прибыль от продаж = 0 | B44: =B6-B7-B8-B9 | C44: =C6-C7-C8-C9
A45: Выручка по направлениям − общая выручка = 0 | B45: =SUM(B23:B28)-B4 | C45: =SUM(C23:C28)-C4
A46: Активы − капитал − краткосрочные − долгосрочные = 0 | B46: =B33-B38-B39-B40 | C46: =C33-C38-C39-C40 | D46: =D33-D38-D39-D40 | E46: Проверка баланса на три даты. Должно быть 0.
A47: Пересчет 2024 в отчете за 2025: основные средства 1150 434 810,069 → 456 703,330; дебиторка 1230 551 374,246 → 348 152,276 (длинная часть ушла в прочие внеоборотные); раздел IV 97 463,751 → 97 807,535; раздел V 403 523,242 → 403 179,458. Себестоимость 2120 сдвинута всего на 20,458 тыс. руб. Со старой редакцией баланса 2024 эти строки не смешивать.
A49: Дополнение из пояснений (значения, не формулы). ИИ эти строки не придумывает.
A50: Показатель | B50: 2024 | C50: 2025 | D50: 31.12.2023, если есть | E50: Откуда
A51: НДПИ в расходах по обычным видам деятельности | B51: 573971.86 | C51: 401238.92 | D51: — | E51: Пояснение 12, внутри прочих затрат. Не строка 2410. В пояснении 10 начисление НДПИ за 2024 — 588 403,461 (без уточненных деклараций); в расчет затрат беру пояснение 12.
A52: НДД в расходах по обычным видам деятельности | B52: 172891.18 | C52: 124338.71 | D52: — | E52: Пояснение 12. В пояснении 10 за 2024 указано 172 810,003. Для элементов затрат — пояснение 12.
A53: Возвратный (отрицательный) акциз | B53: -319222.5 | C53: -179499.64 | D53: — | E53: Пояснение 12. Отрицательное число уменьшает расходы. В 2025 модуль меньше.
A54: Обязательство по ликвидации ОС, поисковых активов и восстановлению ресурсов, конец года | B54: 27815.623 | C54: 34170.902 | D54: 29997.641 | E54: Пояснение 19. 31.12.2023 = начало 2024. Рост 2025 в пояснении в основном из-за снижения ставки дисконтирования.
A55: Курсовая разница, нетто (доход «+», расход «−») | B55: 15941.648 | C55: -25801.544 | D55: — | E55: Пояснение 14, свернуто. Валово 2025: доход 29 481,925, расход 55 283,469.
A56: Резерв под обесценение финансовых вложений, расход в ОФР | B56: 4154.551 | C56: 17917.292 | D56: — | E56: Пояснение 14, свернуто. В основном займы дочерним обществам за пределами РФ.
...

Sheet 2 Горизонтальный
A1: Задание 2. Горизонтальный анализ
A3: Показатель | B3: 2024 | C3: 2025 | D3: Изменение, млн руб. | E3: Темп роста, % | F3: Темп прироста, % | G3: Экономический вывод
A4: Выручка | B4: ='1 Исходные данные'!B4 | C4: ='1 Исходные данные'!C4 | D4: =C4-B4 | E4: =C4/B4*100 | F4: =E4-100 | G4: Выручка снизилась
A5: Себестоимость продаж | B5: ='1 Исходные данные'!B5 | C5: ='1 Исходные данные'!C5 | D5: =C5-B5 | E5: =C5/B5*100 | F5: =E5-100 | G5: Затраты сократились медленнее выручки
A6: Валовая прибыль | B6: ='1 Исходные данные'!B6 | C6: ='1 Исходные данные'!C6 | D6: =C6-B6 | E6: =C6/B6*100 | F6: =E6-100 | G6: Валовая прибыль уменьшилась
A7: Коммерческие расходы | B7: ='1 Исходные данные'!B7 | C7: ='1 Исходные данные'!C7 | D7: =C7-B7 | E7: =C7/B7*100 | F7: =E7-100 | G7: Коммерческие расходы сократились
A8: Управленческие расходы | B8: ='1 Исходные данные'!B8 | C8: ='1 Исходные данные'!C8 | D8: =C8-B8 | E8: =C8/B8*100 | F8: =E8-100 | G8: Управленческие расходы почти стабильны
A9: Прибыль от продаж | B9: ='1 Исходные данные'!B9 | C9: ='1 Исходные данные'!C9 | D9: =C9-B9 | E9: =C9/B9*100 | F9: =E9-100 | G9: Основное падение уже на уровне продаж
A10: Прибыль до налогообложения | B10: ='1 Исходные данные'!B10 | C10: ='1 Исходные данные'!C10 | D10: =C10-B10 | E10: =C10/B10*100 | F10: =E10-100 | G10: Ниже прибыли от продаж просадка сильнее. Одной строкой 2350 это не объясняется: см. пояснение 14.
A11: Чистая прибыль | B11: ='1 Исходные данные'!B11 | C11: ='1 Исходные данные'!C11 | D11: =C11-B11 | E11: =C11/B11*100 | F11: =E11-100 | G11: Чистая прибыль сократилась
A12: НДПИ в расходах по обычным видам | B12: ='1 Исходные данные'!B51 | C12: ='1 Исходные данные'!C51 | D12: =C12-B12 | E12: =IF(B12=0,"—",C12/B12*100) | F12: =IF(B12=0,"—",E12-100) | G12: НДПИ упал сильнее выручки. Это не экономия на добыче.
A13: НДД в расходах по обычным видам | B13: ='1 Исходные данные'!B52 | C13: ='1 Исходные данные'!C52 | D13: =C13-B13 | E13: =IF(B13=0,"—",C13/B13*100) | F13: =IF(B13=0,"—",E13-100) | G13: НДД тоже ниже. К строке 2410 его прибавлять нельзя.
A14: Возвратный (отрицательный) акциз | B14: ='1 Исходные данные'!B53 | C14: ='1 Исходные данные'!C53 | D14: =C14-B14 | E14: =IF(B14=0,"—",C14/B14*100) | F14: =IF(B14=0,"—",E14-100) | G14: Модуль акциза меньше, поддержка затрат ослабла.
A15: Отраслевой анализ причин изменения результата
A16: По пояснению 11, выручка от реализации собственной нефти снизилась на 162 286,909 млн руб. — 88,3% общего падения выручки. | E16: Падение нефтяной выручки не следует без проверки считать падением физической добычи: требуются цены, объемы, структура и курсовые факторы.
A17: Выручка от нефтепродуктов и нефтехимии снизилась на 26 167,960 млн руб.; сокращение расходов на 6,4% не компенсировало снижение выручки на 11,8%. | E17: НДПИ, НДД и возвратный акциз вынесены в строки 12–14 по пояснению 12. Цену, физический объем и логистику из РСБУ по-прежнему не выделить.
A18: Чистая прибыль снизилась быстрее операционной (−42,0% против −30,2%): проверены прочие статьи и налог. | E18: Прочие расходы выросли на 127 934,059 млн руб.; само по себе это НЕ доказывает конкретную причину без детализации пояснения 14.

Sheet 3 Вертикальный
A1: Задание 3. Вертикальный анализ
A3: Показатель | B3: 2024, % | C3: 2025, % | D3: Изменение, п. п. | E3: Интерпретация
A4: Себестоимость продаж/Выручка | B4: ='1 Исходные данные'!B5/'1 Исходные данные'!B4*100 | C4: ='1 Исходные данные'!C5/'1 Исходные данные'!C4*100 | D4: =C4-B4 | E4: Доля себестоимости увеличилась
A5: Валовая прибыль/Выручка | B5: ='1 Исходные данные'!B6/'1 Исходные данные'!B4*100 | C5: ='1 Исходные данные'!C6/'1 Исходные данные'!C4*100 | D5: =C5-B5 | E5: Валовая маржа снизилась
A6: Коммерческие расходы/Выручка | B6: ='1 Исходные данные'!B7/'1 Исходные данные'!B4*100 | C6: ='1 Исходные данные'!C7/'1 Исходные данные'!C4*100 | D6: =C6-B6 | E6: Доля коммерческих расходов чуть ниже
A7: Управленческие расходы/Выручка | B7: ='1 Исходные данные'!B8/'1 Исходные данные'!B4*100 | C7: ='1 Исходные данные'!C8/'1 Исходные данные'!C4*100 | D7: =C7-B7 | E7: Управленческие расходы стали тяжелее
A8: Прибыль от продаж/Выручка | B8: ='1 Исходные данные'!B9/'1 Исходные данные'!B4*100 | C8: ='1 Исходные данные'!C9/'1 Исходные данные'!C4*100 | D8: =C8-B8 | E8: Операционная маржа снизилась
A9: Чистая прибыль/Выручка | B9: ='1 Исходные данные'!B11/'1 Исходные данные'!B4*100 | C9: ='1 Исходные данные'!C11/'1 Исходные данные'!C4*100 | D9: =C9-B9 | E9: Чистая маржа снизилась

Sheet 4 Маржинальность
A1: Задание 4. Маржинальность и EBITDA
A3: Показатель | B3: 2024 | C3: 2025 | D3: Изменение | E3: Формула
A4: Валовая маржа, % | B4: ='1 Исходные данные'!B6/'1 Исходные данные'!B4*100 | C4: ='1 Исходные данные'!C6/'1 Исходные данные'!C4*100 | D4: =C4-B4 | E4: Валовая прибыль / Выручка × 100 %
A5: Операционная маржа, % | B5: ='1 Исходные данные'!B9/'1 Исходные данные'!B4*100 | C5: ='1 Исходные данные'!C9/'1 Исходные данные'!C4*100 | D5: =C5-B5 | E5: Прибыль от продаж / Выручка × 100 %
A6: Чистая маржа, % | B6: ='1 Исходные данные'!B11/'1 Исходные данные'!B4*100 | C6: ='1 Исходные данные'!C11/'1 Исходные данные'!C4*100 | D6: =C6-B6 | E6: Чистая прибыль / Выручка × 100 %
A7: EBITDA, млн руб. | B7: ='1 Исходные данные'!B9+'1 Исходные данные'!B12 | C7: ='1 Исходные данные'!C9+'1 Исходные данные'!C12 | D7: =C7-B7 | E7: Прибыль от продаж +Амортизация
A8: EBITDA margin, % | B8: =B7/'1 Исходные данные'!B4*100 | C8: =C7/'1 Исходные данные'!C4*100 | D8: =C8-B8 | E8: EBITDA / Выручка × 100 %
A9: Коэффициент затрат, % | B9: ='1 Исходные данные'!B5/'1 Исходные данные'!B4*100 | C9: ='1 Исходные данные'!C5/'1 Исходные данные'!C4*100 | D9: =C9-B9 | E9: Себестоимость / Выручка × 100 %
A11: Почему EBITDA может расти при падении чистой прибыли. Здесь так не вышло: EBITDA* тоже снизилась (строка выше). Рост бывает, если амортизация прибавляется сильнее, чем падает прибыль от продаж, или если чистую прибыль режут процент, налог и прочие статьи. Амортизация выросла примерно на 5,3 млрд, прибыль от продаж упала примерно на 96,5 млрд, поэтому запас не перекрыт.
A12: Почему EBITDA* не равна денежному потоку. В 2025 разница EBITDA* − ОДП положительная и большая: в показателе нет уплаты налога, процентов деньгами и движения дебиторки, запасов и резервов. ОДП берется из ОДДС, строка 4100, а не из ОФР.
A13: Амортизация для ТЭК. Рост на 15,0% сам по себе не доказывает ввод новых мощностей: могла измениться база, обесценение, сроки. Учебная EBITDA* = прибыль от продаж + амортизация из пояснения 12. Это не консолидированная EBITDA группы по МСФО и она не вычитает вложения в поддержание добычи.

Sheet 5 Факторный
A1: Задание 5. Факторный анализ выручки
A3: Официальный вид выручки | B3: 2024, млн | C3: 2025, млн | D3: Влияние, млн | E3: Доля общ. измен., %
A4: Выручка: нефтепродукты и нефтехимия | B4: ='1 Исходные данные'!B23 | C4: ='1 Исходные данные'!C23 | D4: =C4-B4 | E4: =D4/$D$10*100
A5: Выручка: собственная нефть | B5: ='1 Исходные данные'!B24 | C5: ='1 Исходные данные'!C24 | D5: =C5-B5 | E5: =D5/$D$10*100
A6: Выручка: прочие готовые товары | B6: ='1 Исходные данные'!B25 | C6: ='1 Исходные данные'!C25 | D6: =C6-B6 | E6: =D6/$D$10*100
A7: Выручка: покупная нефть | B7: ='1 Исходные данные'!B26 | C7: ='1 Исходные данные'!C26 | D7: =C7-B7 | E7: =D7/$D$10*100
A8: Выручка: строительные работы | B8: ='1 Исходные данные'!B27 | C8: ='1 Исходные данные'!C27 | D8: =C8-B8 | E8: =D8/$D$10*100
A9: Выручка: прочая реализация | B9: ='1 Исходные данные'!B28 | C9: ='1 Исходные данные'!C28 | D9: =C9-B9 | E9: =D9/$D$10*100
A10: ИТОГО, изменение выручки | B10: =SUM(B4:B9) | C10: =SUM(C4:C9) | D10: =SUM(D4:D9) | E10: =D10/$D$10*100
A12: Проверка: сумма влияний − изменение выручки | D12: =D10-('1 Исходные данные'!C4-'1 Исходные данные'!B4) | E12: Должно быть 0.
A13: Цепные подстановки «объем × цена» не считаю. В отчете нет Q и P, а выдумывать их нельзя. Разрез ниже — по видам выручки из пояснения 11. Основной минус дает собственная нефть. Покупная нефть выросла с нуля и частично этот минус закрывает, но мало. Инфляционный рост цены тут вообще нечего обсуждать как факт года: цены реализации в рублях на тонну в отчетности нет.

Sheet 6 Качество прибыли
A1: Задание 6. Качество прибыли
A3: Показатель | B3: 2024 | C3: 2025 | D3: Изменение
A4: Чистая прибыль | B4: ='1 Исходные данные'!B11 | C4: ='1 Исходные данные'!C11 | D4: =C4-B4
A5: Операционный денежный поток | B5: ='1 Исходные данные'!B13 | C5: ='1 Исходные данные'!C13 | D5: =C5-B5
A6: Коэффициент денежного качества | B6: =B5/B4 | C6: =C5/C4 | D6: =C6-B6
A7: Инвестиционные денежные CAPEX | B7: ='1 Исходные данные'!B14 | C7: ='1 Исходные данные'!C14 | D7: =C7-B7
A8: Капвложения, учтенные в текущих операциях | B8: ='1 Исходные данные'!B15 | C8: ='1 Исходные данные'!C15 | D8: =C8-B8
A9: Всего денежные капитальные платежи | B9: =SUM(B7:B8) | C9: =SUM(C7:C8) | D9: =C9-B9
A10: Условный поток после инвест. CAPEX = ОДП − 4221 | B10: =B5-B7 | C10: =C5-C7 | D10: =C10-B10
A11: Дебиторская задолженность | B11: ='1 Исходные данные'!B36 | C11: ='1 Исходные данные'!C36 | D11: =C11-B11
A12: Запасы | B12: ='1 Исходные данные'!B35 | C12: ='1 Исходные данные'!C35 | D12: =C12-B12
A13: Денежные средства | B13: ='1 Исходные данные'!B37 | C13: ='1 Исходные данные'!C37 | D13: =C13-B13
A15: Вывод. Коэффициент вырос с 1,16 до 1,42, потому что чистая прибыль сжалась сильнее операционного потока. Оба показателя в абсолюте ниже, так что «качество улучшилось» из одного частного не следует. Дебиторка и запасы снизились, это поддерживает ОДП, но деньги на счетах тоже меньше. Часть провала ниже операционной прибыли неденежная: курсовая разница и резервы из пояснения 14. Строку 4125 второй раз из ОДП не вычитаю, она уже внутри строки 4100. После инвестиционных платежей 4221 остается ОДП − 4221.

Sheet 8 Проверка ИИ
A1: Задание 8. Контроль ответа Grok и моей расчетной таблицы
A3: Утверждение (с указанием, где оно было) | B3: Статус | C3: Как проверено / формула | D3: Проверка: число | E3: Исправление, смысл и ограничение
A4: 01. Ответ ИИ, п. 1: выручка 2025 снизилась на 11,8%. | B4: подтверждено | C4: (ОФР 2110_25/2110_24−1)×100 | D4: =('1 Исходные данные'!C4/'1 Исходные данные'!B4-1)*100 | E4: −11,76% (округл. −11,8%). Исходная учебная ситуация о росте выручки для этой компании не выполняется.
A5: 02. Ответ ИИ, п. 2: себестоимость уменьшилась на 6,4%. | B5: подтверждено частично | C5: ОФР 2120, сопоставимая графа 2024 | D5: =('1 Исходные данные'!C5/'1 Исходные данные'!B5-1)*100 | E5: Число верно при использовании ПЕРЕСЧИТАННОЙ базы 2024 из отчета за 2025. Смешивать с прежней версией 2024 нельзя.
A6: 03. Ответ ИИ, п. 2: валовая прибыль упала на 25,2%. | B6: подтверждено | C6: ОФР 2100, проверка R−С | D6: =('1 Исходные данные'!C6/'1 Исходные данные'!B6-1)*100 | E6: Да, −25,15%. Себестоимость снижалась медленнее выручки — пониженная валовая маржа.
A7: 04. Ответ ИИ, п. 3: валовая маржа 2025 = 24,17%. | B7: подтверждено | C7: 333578,094 / 1379916,414 ×100 | D7: ='1 Исходные данные'!C6/'1 Исходные данные'!C4*100 | E7: 24,17%; падение на 4,32 п. п. означает ослабление защиты от ценовых шоков нефти/нефтепродуктов.
A8: 05. Ответ ИИ, п. 4: операционная маржа 16,13%. | B8: подтверждено | C8: 2200 / 2110 ×100 | D8: ='1 Исходные данные'!C9/'1 Исходные данные'!C4*100 | E8: Это маржа ПАО по РСБУ, не всей группы «Татнефть» по МСФО.
A9: 06. Ответ ИИ, п. 5: чистая прибыль −42,0%. | B9: подтверждено | C9: ОФР 2400, 2024 и 2025 | D9: =('1 Исходные данные'!C11/'1 Исходные данные'!B11-1)*100 | E9: −41,98%. Снижена способность финансировать капвложения из прибыли; это не то же самое, что сокращение денег на счетах.
A10: 07. Ответ ИИ, п. 5: «прочие расходы ослабили результат». | B10: подтверждено частично | C10: 2350_25−2350_24 | D10: ='1 Исходные данные'!C20-'1 Исходные данные'!B20 | E10: Прочие расходы выросли на 127 934,059 млн руб., но одновременно росли и прочие доходы; для причин необходима детализация прим. 14.
A11: 08. Ответ ИИ, п. 6: EBITDA* 2025 = 263568,979. | B11: подтверждено частично | C11: 2200 + амортизация из прим. 12 | D11: ='1 Исходные данные'!C9+'1 Исходные данные'!C12 | E11: Учебная EBITDA* верна, но не официальная консолидированная EBITDA. ТЭК: не покрывает вложения в поддержание добычи.
A12: 09. Ответ ИИ, п. 6: амортизация выросла на 15,0%. | B12: подтверждено | C12: Амортизация_25 / Амортизация_24 −1 | D12: =('1 Исходные данные'!C12/'1 Исходные данные'!B12-1)*100 | E12: Рост амортизации может сопровождать изменение базы активов, но нельзя автоматически утверждать, что введены новые мощности.
A13: 10. Ответ ИИ, п. 7: ОДП сократился на 29,1%. | B13: подтверждено | C13: ОДДС 4100 за два года | D13: =('1 Исходные данные'!C13/'1 Исходные данные'!B13-1)*100 | E13: Операционный денежный поток снизился. Для капиталоёмкой отрасли важен именно запас денежных средств после необходимых инвестиций.
A14: 11. Ответ ИИ, п. 7: ОДП ниже EBITDA*, не равен ей. | B14: подтверждено | C14: EBITDA* − ОДП в 2025 | D14: ='4 Маржинальность'!C7-'1 Исходные данные'!C13 | E14: Разница 56 560,221 млн руб.; EBITDA* не учитывает налоговые платежи, оборотный капитал и часть иных платежей.
A15: 12. Ответ ИИ, п. 8: ОДП/ЧП вырос до 1,42. | B15: подтверждено частично | C15: 207008,758 / 145844,143 | D15: ='1 Исходные данные'!C13/'1 Исходные данные'!C11 | E15: 1,42 верно. Но нельзя делать сильный вывод об улучшении качества прибыли: оба абсолютных показателя снизились, ЧП — быстрее.
A16: 13. Ответ ИИ, п. 9: цену и объём нельзя отделить по РСБУ. | B16: подтверждено | C16: Для R=ΣPiQi требуются Qi,Pi по видам | E16: В отчете есть рублевая выручка по продуктам, но нет единого Q и P. Падение нефтяной выручки нельзя считать уменьшением добычи.
A17: 14. Ответ ИИ, п. 10: стресс выручки 1179828,534. | B17: подтверждено | C17: R0×0,90×0,95 | D17: ='9 Сценарный анализ'!C11 | E17: −14,5%, а не −15%: цена и объем действуют мультипликативно. Это сценарий, не официальный прогноз.
A18: 15. Ответ ИИ, п. 10: стресс себестоимости 1063602,902. | B18: подтверждено частично | C18: С0×0,95×1,07 | D18: ='9 Сценарный анализ'!C12 | E18: Подстановка верна только при допущении 100% переменных затрат; в реальном ТЭК есть затраты постоянного характера.
A19: 16. Ответ ИИ, п. 12: стресс чистой прибыли −71508,319. | B19: подтверждено частично | C19: Сохранение расхода по налогу 2025 | D19: ='9 Сценарный анализ'!C22 | E19: Это альтернативная чувствительность с неизменным налогом. Основной сценарий при нулевом условном налоговом расходе дает меньший убыток.
A20: 17. ОДП−(4221+4125). | B20: методическая ошибка | C20: 4100 уже включает 4125; вычитать только 4221 | D20: ='6 Качество прибыли'!C10 | E20: Исправлено до 139 649,620 млн руб. (было 108 135,904).
A22: Заключение проверки ИИ и методические ограничения
A23: Сохранённый ответ ИИ | E23: 17 пунктов ответа Grok. Проверялись заявленные числа и выводы, не пересказ.
A24: Что подтверждено | E24: Большинство базовых чисел, маржа, EBITDA*, снижение ОДП и математическое ядро стресса.
A25: Что исправлено | E25: Двойной счёт CAPEX, неучтённый переход прибыли в убыток при стрессе, пустая оценка рисков, разграничение EBITDA и ДДС.
A26: Что не разрешено выдавать за факт | E26: Причины падения добычи, эффект цены/объема без Q и P, состав постоянных расходов, официальная консолидированная EBITDA, точный налог стресса.

Sheet 9 Сценарный анализ
A1: Задание 9. Стресс-тест ПАО «Татнефть», РСБУ 2025
A3: Сценарные предпосылки | B3: Значение
A4: Цена реализации (изменение) | B4: -0.1
A5: Физический объем (изменение) | B5: -0.05
A6: Удельная себестоимость (изменение) | B6: 0.07
A8: Показатель | B8: База: 2025 | C8: Стресс | D8: Изменение | E8: Оценка риска
A9: Объем, индекс 2025=100 | B9: ='1 Исходные данные'!C4/'1 Исходные данные'!C4*100 | C9: =B9*(1+$B$5) | D9: =C9-B9 | E9: −5 индексных пунктов. НЕДОЗАГРУЗКА: поддерживающие ремонты, промбезопасность и часть производственных расходов не сокращаются пропорционально добыче.
A10: Средняя цена, индекс 2025=100 | B10: ='1 Исходные данные'!C4/'1 Исходные данные'!C4*100 | C10: =B10*(1+$B$4) | D10: =C10-B10 | E10: −10 индексных пунктов. ЦЕНОВОЙ РИСК: котировки нефти и нефтепродуктов, курс рубля, экспортные условия и перерабатывающий спред; индекс, не фактическая средняя цена.
A11: Выручка, млн руб. | B11: ='1 Исходные данные'!C4 | C11: =B11*(C9/B9)*(C10/B10) | D11: =C11-B11 | E11: −200 087,880 млн руб. (−14,5%). ВЫСОКИЙ: сочетание объема −5% и цены −10%; снижение выручки нефтяного бизнеса давит на валовую маржу.
A12: Себестоимость, млн руб. | B12: ='1 Исходные данные'!C5 | C12: =B12*(C9/B9)*(1+$B$6) | D12: =C12-B12 | E12: +17 264,582 млн руб. (+1,65%) при Q −5% и удельных затратах +7%. ВЫСОКИЙ: энергия, реагенты, обслуживание оборудования и технологические ограничения.
A13: Валовая прибыль, млн руб. | B13: ='1 Исходные данные'!C6 | C13: =C11-C12 | D13: =C13-B13 | E13: −217 352,462 млн руб. (−65,2%); валовая маржа 24,17% → 9,85%, −14,32 п. п. КРИТИЧЕСКИЙ: малый запас на производственные и логистические шоки.
A14: EBITDA, млн руб. | B14: ='1 Исходные данные'!C9+'1 Исходные данные'!C12 | C14: =C13-'1 Исходные данные'!C7-'1 Исходные данные'!C8+'1 Исходные данные'!C12 | D14: =C14-B14 | E14: −217 352,462 млн руб. (−82,5%); EBITDA* margin 19,10% → 3,92%. КРИТИЧЕСКИЙ: покрытие поддерживающих капиталовложений ухудшается.
A15: Чистая прибыль, млн руб. | B15: ='1 Исходные данные'!C11 | C15: =C19-C20+C21 | D15: =C15-B15 | E15: При допущении нулевого расхода по налогу результат −27 445,449 млн руб. (вместо прибыли 145 844,143). КРИТИЧЕСКИЙ: резервы, убыток и ограничение финансирования.
A16: Денежные капитальные платежи 4221 + 4125 | B16: ='1 Исходные данные'!C14+'1 Исходные данные'!C15 | C16: =B16 | D16: =C16-B16 | E16: 98 872,854 млн руб. без изменения, в 2,14 раза выше стрессовой EBITDA*. ВЫСОКИЙ: плановой CAPEX нет; нельзя отменять промбезопасность, ремонты и рекультивацию.
A18: Мостик к чистой прибыли. Коммерческие, управленческие и строки 2310–2350 не двигаю. Это допущение сценария.
A19: Прибыль до налогообложения | B19: ='1 Исходные данные'!C10 | C19: =B19+(C13-B13) | D19: =C19-B19 | E19: Сдвиг равен изменению валовой прибыли: коммерческие и управленческие зафиксированы.
A20: Условный расход по налогу (0, если до налога убыток; иначе расход 2025 без пересчета ставки) | B20: ='1 Исходные данные'!C21 | C20: =IF(C19<=0,0,B20) | D20: =C20-B20 | E20: Основной сценарий. На убыток до налога расход 2025 не навешиваю.
A21: Строка 2460, без изменения | B21: ='1 Исходные данные'!C22 | C21: =B21 | D21: =C21-B21 | E21: Состав строки не расшифрован, поэтому не обнуляю.
A22: Альтернатива: чистая прибыль, если налог 2025 не обнулять | B22: ='1 Исходные данные'!C11 | C22: =C19-B20+C21 | D22: =C22-B22 | E22: Это число из ответа ИИ (−71 508). Оно не основной сценарий.
A23: Валовая маржа, % | B23: =IF(B11=0,"—",B13/B11*100) | C23: =IF(C11=0,"—",C13/C11*100) | D23: =C23-B23 | E23: Считается из выручки и валовой прибыли стресса, не вручную.
A24: EBITDA* margin, % | B24: =IF(B11=0,"—",B14/B11*100) | C24: =IF(C11=0,"—",C14/C11*100) | D24: =C24-B24 | E24: Та же логика.
A25: Денежные капвложения / EBITDA*, % | B25: =IF(B14=0,"—",B16/B14*100) | C25: =IF(C14=0,"—",C16/C14*100) | D25: =C25-B25 | E25: На это ссылается индикатор по капвложениям ниже.
A31: Реестр рисков ТЭК: подтверждения, последствия, ответ
A32: Риск / сегмент | B32: Оценка | C32: Подтверждённый индикатор | D32: Потенциальное последствие | E32: Действие без ущерба безопасности
A33: Реализация собственной нефти | B33: Высокий | C33: ='1 Исходные данные'!C24-'1 Исходные данные'!B24 | D33: Снижение нефтяной выручки на 162 286,909 млн руб. — 88,3% совокупного падения. Нельзя объяснять всё сокращением добычи. | E33: Контроль валютной и ценовой чувствительности, условий реализации, продаж по направлениям; запросить физический объем.
A34: Нефтепродукты/нефтехимия | B34: Высокий | C34: ='1 Исходные данные'!C23-'1 Исходные данные'!B23 | D34: Выручка по сегменту меньше на 26 167,960 млн руб.: давление на продуктовую/перерабатывающую маржу. | E34: Оптимизировать выпуск продукции и энергопотребление с учетом ограничений технологического режима и качества.
A35: Экспорт, курс, котировки | B35: Нужна детализация | D35: Валютную/ценовую часть изменения выручки нельзя выделить из агрегированного РСБУ; иная география торговли меняет стоимость логистики. | E35: Запросить контрактные цены, валюты расчетов, хеджирование, доли экспорта; не приписывать конкретный эффект без данных.
A36: Налоги / акцизы / НДПИ | B36: Высокий | C36: ='1 Исходные данные'!C21 | D36: Расход по налогу на прибыль 44 062,870 млн руб.; НДПИ и акцизы относятся к другой налоговой базе и НЕ равны этой строке. | E36: Отдельно моделировать налоги на добычу, переработку и финансовый результат; не применять к убытку неизменный налог механически.
A37: Капвложения и обновление | B37: Высокий | C37: ='9 Сценарный анализ'!C25 | D37: Денежный CAPEX при стрессе составил бы 213,9% EBITDA*; высока угроза приостановки расширений при сохранении обязательных работ. | E37: Разделить поддерживающий и расширяющий CAPEX; первыми защищать безопасность, ремонт скважин и экологию.
A38: Рекультивация и вывод скважин | B38: Высокий | C38: ='1 Исходные данные'!C54-'1 Исходные данные'!B54 | D38: Обязательство по ликвидации и восстановлению выросло на 6 355,279 млн руб. (пояснение 19). В тексте пояснения причина в основном — снижение ставки дисконтирования. При стрессе цены оно не исчезает. | E38: Проверить резервы на ликвидацию объектов и рекультивацию, график будущих выплат и ставки дисконтирования.
A39: Ремонт и непрерывность добычи | B39: Высокий | D39: Сокращение объема не уменьшает расходы на промбезопасность пропорционально: простой/авария способны усилить потери и экологический ущерб. | E39: Ограничения на сокращение регламентного ремонта и контроля; повышать энергоэффективность технологическими мерами.
A40: Ликвидность и платежи | B40: Высокий | C40: ='1 Исходные данные'!C37-'1 Исходные данные'!B37 | D40: Денежные средства на 31.12.2025 ниже на 33 006,933 млн руб.; при стресс-сценарии это сокращает резерв покрытия внезапных платежей. | E40: Платежный календарь, кредитные лимиты и оборотный капитал; не делать вывод о денежных потоках лишь из EBITDA*.
A41: Прочие расходы и неденежные эффекты | B41: Высокий | C41: ='1 Исходные данные'!C20-'1 Исходные данные'!B20 | D41: Прочие расходы выросли на 127 934,059 млн руб.; нужна детализация курсовых/оценочных/разовых статей для причинного вывода. | E41: Расшифровать примечание 14 и отделить денежные/неденежные статьи от устойчивого операционного результата.
